2023-01-10 07:53:43,716 ERROR: Exception on /edit_profile [POST] [in C:\Users\grc2639\Downloads\MScDSA\python\microblog\venv\lib\site-packages\flask\app.py:1741]
Traceback (most recent call last):
  File "C:\Users\grc2639\Downloads\MScDSA\python\microblog\venv\lib\site-packages\sqlalchemy\engine\base.py", line 1900, in _execute_context
    self.dialect.do_execute(
  File "C:\Users\grc2639\Downloads\MScDSA\python\microblog\venv\lib\site-packages\sqlalchemy\engine\default.py", line 736, in do_execute
    cursor.execute(statement, parameters)
sqlite3.IntegrityError: UNIQUE constraint failed: user.username

The above exception was the direct cause of the following exception:

Traceback (most recent call last):
  File "C:\Users\grc2639\Downloads\MScDSA\python\microblog\venv\lib\site-packages\flask\app.py", line 2525, in wsgi_app
    response = self.full_dispatch_request()
  File "C:\Users\grc2639\Downloads\MScDSA\python\microblog\venv\lib\site-packages\flask\app.py", line 1822, in full_dispatch_request
    rv = self.handle_user_exception(e)
  File "C:\Users\grc2639\Downloads\MScDSA\python\microblog\venv\lib\site-packages\flask\app.py", line 1820, in full_dispatch_request
    rv = self.dispatch_request()
  File "C:\Users\grc2639\Downloads\MScDSA\python\microblog\venv\lib\site-packages\flask\app.py", line 1796, in dispatch_request
    return self.ensure_sync(self.view_functions[rule.endpoint])(**view_args)
  File "C:\Users\grc2639\Downloads\MScDSA\python\microblog\venv\lib\site-packages\flask_login\utils.py", line 290, in decorated_view
    return current_app.ensure_sync(func)(*args, **kwargs)
  File "C:\Users\grc2639\Downloads\MScDSA\python\microblog\app\routes.py", line 90, in edit_profile
    db.session.commit()
  File "<string>", line 2, in commit
  File "C:\Users\grc2639\Downloads\MScDSA\python\microblog\venv\lib\site-packages\sqlalchemy\orm\session.py", line 1451, in commit
    self._transaction.commit(_to_root=self.future)
  File "C:\Users\grc2639\Downloads\MScDSA\python\microblog\venv\lib\site-packages\sqlalchemy\orm\session.py", line 829, in commit
    self._prepare_impl()
  File "C:\Users\grc2639\Downloads\MScDSA\python\microblog\venv\lib\site-packages\sqlalchemy\orm\session.py", line 808, in _prepare_impl
    self.session.flush()
  File "C:\Users\grc2639\Downloads\MScDSA\python\microblog\venv\lib\site-packages\sqlalchemy\orm\session.py", line 3444, in flush
    self._flush(objects)
  File "C:\Users\grc2639\Downloads\MScDSA\python\microblog\venv\lib\site-packages\sqlalchemy\orm\session.py", line 3583, in _flush
    with util.safe_reraise():
  File "C:\Users\grc2639\Downloads\MScDSA\python\microblog\venv\lib\site-packages\sqlalchemy\util\langhelpers.py", line 70, in __exit__
    compat.raise_(
  File "C:\Users\grc2639\Downloads\MScDSA\python\microblog\venv\lib\site-packages\sqlalchemy\util\compat.py", line 211, in raise_
    raise exception
  File "C:\Users\grc2639\Downloads\MScDSA\python\microblog\venv\lib\site-packages\sqlalchemy\orm\session.py", line 3544, in _flush
    flush_context.execute()
  File "C:\Users\grc2639\Downloads\MScDSA\python\microblog\venv\lib\site-packages\sqlalchemy\orm\unitofwork.py", line 456, in execute
    rec.execute(self)
  File "C:\Users\grc2639\Downloads\MScDSA\python\microblog\venv\lib\site-packages\sqlalchemy\orm\unitofwork.py", line 630, in execute
    util.preloaded.orm_persistence.save_obj(
  File "C:\Users\grc2639\Downloads\MScDSA\python\microblog\venv\lib\site-packages\sqlalchemy\orm\persistence.py", line 237, in save_obj
    _emit_update_statements(
  File "C:\Users\grc2639\Downloads\MScDSA\python\microblog\venv\lib\site-packages\sqlalchemy\orm\persistence.py", line 1001, in _emit_update_statements
    c = connection._execute_20(
  File "C:\Users\grc2639\Downloads\MScDSA\python\microblog\venv\lib\site-packages\sqlalchemy\engine\base.py", line 1705, in _execute_20
    return meth(self, args_10style, kwargs_10style, execution_options)
  File "C:\Users\grc2639\Downloads\MScDSA\python\microblog\venv\lib\site-packages\sqlalchemy\sql\elements.py", line 334, in _execute_on_connection
    return connection._execute_clauseelement(
  File "C:\Users\grc2639\Downloads\MScDSA\python\microblog\venv\lib\site-packages\sqlalchemy\engine\base.py", line 1572, in _execute_clauseelement
    ret = self._execute_context(
  File "C:\Users\grc2639\Downloads\MScDSA\python\microblog\venv\lib\site-packages\sqlalchemy\engine\base.py", line 1943, in _execute_context
    self._handle_dbapi_exception(
  File "C:\Users\grc2639\Downloads\MScDSA\python\microblog\venv\lib\site-packages\sqlalchemy\engine\base.py", line 2124, in _handle_dbapi_exception
    util.raise_(
  File "C:\Users\grc2639\Downloads\MScDSA\python\microblog\venv\lib\site-packages\sqlalchemy\util\compat.py", line 211, in raise_
    raise exception
  File "C:\Users\grc2639\Downloads\MScDSA\python\microblog\venv\lib\site-packages\sqlalchemy\engine\base.py", line 1900, in _execute_context
    self.dialect.do_execute(
  File "C:\Users\grc2639\Downloads\MScDSA\python\microblog\venv\lib\site-packages\sqlalchemy\engine\default.py", line 736, in do_execute
    cursor.execute(statement, parameters)
sqlalchemy.exc.IntegrityError: (sqlite3.IntegrityError) UNIQUE constraint failed: user.username
[SQL: UPDATE user SET username=?, about_me=? WHERE user.id = ?]
[parameters: ('susan', 'This is me!', 2)]
(Background on this error at: https://sqlalche.me/e/14/gkpj)
2023-01-10 07:54:03,273 INFO: MIcroblog startup [in C:\Users\grc2639\Downloads\MScDSA\python\microblog\app\__init__.py:28]
2023-01-11 05:41:32,596 INFO: MIcroblog startup [in C:\Users\grc2639\Downloads\MScDSA\python\microblog\app\__init__.py:28]
2023-01-11 05:41:33,453 ERROR: Exception on /favicon.ico [GET] [in C:\Users\grc2639\Downloads\MScDSA\python\microblog\venv\lib\site-packages\flask\app.py:1741]
Traceback (most recent call last):
  File "C:\Users\grc2639\Downloads\MScDSA\python\microblog\venv\lib\site-packages\flask\app.py", line 1820, in full_dispatch_request
    rv = self.dispatch_request()
  File "C:\Users\grc2639\Downloads\MScDSA\python\microblog\venv\lib\site-packages\flask\app.py", line 1785, in dispatch_request
    self.raise_routing_exception(req)
  File "C:\Users\grc2639\Downloads\MScDSA\python\microblog\venv\lib\site-packages\flask\app.py", line 1767, in raise_routing_exception
    raise request.routing_exception  # type: ignore
  File "C:\Users\grc2639\Downloads\MScDSA\python\microblog\venv\lib\site-packages\flask\ctx.py", line 351, in match_request
    result = self.url_adapter.match(return_rule=True)  # type: ignore
  File "C:\Users\grc2639\Downloads\MScDSA\python\microblog\venv\lib\site-packages\werkzeug\routing\map.py", line 624, in match
    raise NotFound() from None
werkzeug.exceptions.NotFound: 404 Not Found: The requested URL was not found on the server. If you entered the URL manually please check your spelling and try again.

During handling of the above exception, another exception occurred:

Traceback (most recent call last):
  File "C:\Users\grc2639\Downloads\MScDSA\python\microblog\venv\lib\site-packages\flask\app.py", line 2525, in wsgi_app
    response = self.full_dispatch_request()
  File "C:\Users\grc2639\Downloads\MScDSA\python\microblog\venv\lib\site-packages\flask\app.py", line 1822, in full_dispatch_request
    rv = self.handle_user_exception(e)
  File "C:\Users\grc2639\Downloads\MScDSA\python\microblog\venv\lib\site-packages\flask\app.py", line 1666, in handle_user_exception
    return self.handle_http_exception(e)
  File "C:\Users\grc2639\Downloads\MScDSA\python\microblog\venv\lib\site-packages\flask\app.py", line 1606, in handle_http_exception
    return self.ensure_sync(handler)(e)
  File "C:\Users\grc2639\Downloads\MScDSA\python\microblog\app\errors.py", line 6, in not_found_error
    return render_template('404.html'), 404
  File "C:\Users\grc2639\Downloads\MScDSA\python\microblog\venv\lib\site-packages\flask\templating.py", line 146, in render_template
    template = app.jinja_env.get_or_select_template(template_name_or_list)
  File "C:\Users\grc2639\Downloads\MScDSA\python\microblog\venv\lib\site-packages\jinja2\environment.py", line 1081, in get_or_select_template
    return self.get_template(template_name_or_list, parent, globals)
  File "C:\Users\grc2639\Downloads\MScDSA\python\microblog\venv\lib\site-packages\jinja2\environment.py", line 1010, in get_template
    return self._load_template(name, globals)
  File "C:\Users\grc2639\Downloads\MScDSA\python\microblog\venv\lib\site-packages\jinja2\environment.py", line 969, in _load_template
    template = self.loader.load(self, name, self.make_globals(globals))
  File "C:\Users\grc2639\Downloads\MScDSA\python\microblog\venv\lib\site-packages\jinja2\loaders.py", line 138, in load
    code = environment.compile(source, name, filename)
  File "C:\Users\grc2639\Downloads\MScDSA\python\microblog\venv\lib\site-packages\jinja2\environment.py", line 768, in compile
    self.handle_exception(source=source_hint)
  File "C:\Users\grc2639\Downloads\MScDSA\python\microblog\venv\lib\site-packages\jinja2\environment.py", line 936, in handle_exception
    raise rewrite_traceback_stack(source=source)
  File "C:\Users\grc2639\Downloads\MScDSA\python\microblog\app\templates\404.html", line 1, in template
    {% extends 'base.html'}
jinja2.exceptions.TemplateSyntaxError: unexpected '}'
