2023-01-11 05:41:40,073 ERROR: Exception on /favicon.ico [GET] [in C:\Users\grc2639\Downloads\MScDSA\python\microblog\venv\lib\site-packages\flask\app.py:1741]
Traceback (most recent call last):
  File "C:\Users\grc2639\Downloads\MScDSA\python\microblog\venv\lib\site-packages\flask\app.py", line 1820, in full_dispatch_request
    rv = self.dispatch_request()
  File "C:\Users\grc2639\Downloads\MScDSA\python\microblog\venv\lib\site-packages\flask\app.py", line 1785, in dispatch_request
    self.raise_routing_exception(req)
  File "C:\Users\grc2639\Downloads\MScDSA\python\microblog\venv\lib\site-packages\flask\app.py", line 1767, in raise_routing_exception
    raise request.routing_exception  # type: ignore
  File "C:\Users\grc2639\Downloads\MScDSA\python\microblog\venv\lib\site-packages\flask\ctx.py", line 351, in match_request
    result = self.url_adapter.match(return_rule=True)  # type: ignore
  File "C:\Users\grc2639\Downloads\MScDSA\python\microblog\venv\lib\site-packages\werkzeug\routing\map.py", line 624, in match
    raise NotFound() from None
werkzeug.exceptions.NotFound: 404 Not Found: The requested URL was not found on the server. If you entered the URL manually please check your spelling and try again.

During handling of the above exception, another exception occurred:

Traceback (most recent call last):
  File "C:\Users\grc2639\Downloads\MScDSA\python\microblog\venv\lib\site-packages\flask\app.py", line 2525, in wsgi_app
    response = self.full_dispatch_request()
  File "C:\Users\grc2639\Downloads\MScDSA\python\microblog\venv\lib\site-packages\flask\app.py", line 1822, in full_dispatch_request
    rv = self.handle_user_exception(e)
  File "C:\Users\grc2639\Downloads\MScDSA\python\microblog\venv\lib\site-packages\flask\app.py", line 1666, in handle_user_exception
    return self.handle_http_exception(e)
  File "C:\Users\grc2639\Downloads\MScDSA\python\microblog\venv\lib\site-packages\flask\app.py", line 1606, in handle_http_exception
    return self.ensure_sync(handler)(e)
  File "C:\Users\grc2639\Downloads\MScDSA\python\microblog\app\errors.py", line 6, in not_found_error
    return render_template('404.html'), 404
  File "C:\Users\grc2639\Downloads\MScDSA\python\microblog\venv\lib\site-packages\flask\templating.py", line 146, in render_template
    template = app.jinja_env.get_or_select_template(template_name_or_list)
  File "C:\Users\grc2639\Downloads\MScDSA\python\microblog\venv\lib\site-packages\jinja2\environment.py", line 1081, in get_or_select_template
    return self.get_template(template_name_or_list, parent, globals)
  File "C:\Users\grc2639\Downloads\MScDSA\python\microblog\venv\lib\site-packages\jinja2\environment.py", line 1010, in get_template
    return self._load_template(name, globals)
  File "C:\Users\grc2639\Downloads\MScDSA\python\microblog\venv\lib\site-packages\jinja2\environment.py", line 969, in _load_template
    template = self.loader.load(self, name, self.make_globals(globals))
  File "C:\Users\grc2639\Downloads\MScDSA\python\microblog\venv\lib\site-packages\jinja2\loaders.py", line 138, in load
    code = environment.compile(source, name, filename)
  File "C:\Users\grc2639\Downloads\MScDSA\python\microblog\venv\lib\site-packages\jinja2\environment.py", line 768, in compile
    self.handle_exception(source=source_hint)
  File "C:\Users\grc2639\Downloads\MScDSA\python\microblog\venv\lib\site-packages\jinja2\environment.py", line 936, in handle_exception
    raise rewrite_traceback_stack(source=source)
  File "C:\Users\grc2639\Downloads\MScDSA\python\microblog\app\templates\404.html", line 1, in template
    {% extends 'base.html'}
jinja2.exceptions.TemplateSyntaxError: unexpected '}'
2023-01-11 05:41:45,915 ERROR: Exception on /favicon.ico [GET] [in C:\Users\grc2639\Downloads\MScDSA\python\microblog\venv\lib\site-packages\flask\app.py:1741]
Traceback (most recent call last):
  File "C:\Users\grc2639\Downloads\MScDSA\python\microblog\venv\lib\site-packages\flask\app.py", line 1820, in full_dispatch_request
    rv = self.dispatch_request()
  File "C:\Users\grc2639\Downloads\MScDSA\python\microblog\venv\lib\site-packages\flask\app.py", line 1785, in dispatch_request
    self.raise_routing_exception(req)
  File "C:\Users\grc2639\Downloads\MScDSA\python\microblog\venv\lib\site-packages\flask\app.py", line 1767, in raise_routing_exception
    raise request.routing_exception  # type: ignore
  File "C:\Users\grc2639\Downloads\MScDSA\python\microblog\venv\lib\site-packages\flask\ctx.py", line 351, in match_request
    result = self.url_adapter.match(return_rule=True)  # type: ignore
  File "C:\Users\grc2639\Downloads\MScDSA\python\microblog\venv\lib\site-packages\werkzeug\routing\map.py", line 624, in match
    raise NotFound() from None
werkzeug.exceptions.NotFound: 404 Not Found: The requested URL was not found on the server. If you entered the URL manually please check your spelling and try again.

During handling of the above exception, another exception occurred:

Traceback (most recent call last):
  File "C:\Users\grc2639\Downloads\MScDSA\python\microblog\venv\lib\site-packages\flask\app.py", line 2525, in wsgi_app
    response = self.full_dispatch_request()
  File "C:\Users\grc2639\Downloads\MScDSA\python\microblog\venv\lib\site-packages\flask\app.py", line 1822, in full_dispatch_request
    rv = self.handle_user_exception(e)
  File "C:\Users\grc2639\Downloads\MScDSA\python\microblog\venv\lib\site-packages\flask\app.py", line 1666, in handle_user_exception
    return self.handle_http_exception(e)
  File "C:\Users\grc2639\Downloads\MScDSA\python\microblog\venv\lib\site-packages\flask\app.py", line 1606, in handle_http_exception
    return self.ensure_sync(handler)(e)
  File "C:\Users\grc2639\Downloads\MScDSA\python\microblog\app\errors.py", line 6, in not_found_error
    return render_template('404.html'), 404
  File "C:\Users\grc2639\Downloads\MScDSA\python\microblog\venv\lib\site-packages\flask\templating.py", line 146, in render_template
    template = app.jinja_env.get_or_select_template(template_name_or_list)
  File "C:\Users\grc2639\Downloads\MScDSA\python\microblog\venv\lib\site-packages\jinja2\environment.py", line 1081, in get_or_select_template
    return self.get_template(template_name_or_list, parent, globals)
  File "C:\Users\grc2639\Downloads\MScDSA\python\microblog\venv\lib\site-packages\jinja2\environment.py", line 1010, in get_template
    return self._load_template(name, globals)
  File "C:\Users\grc2639\Downloads\MScDSA\python\microblog\venv\lib\site-packages\jinja2\environment.py", line 969, in _load_template
    template = self.loader.load(self, name, self.make_globals(globals))
  File "C:\Users\grc2639\Downloads\MScDSA\python\microblog\venv\lib\site-packages\jinja2\loaders.py", line 138, in load
    code = environment.compile(source, name, filename)
  File "C:\Users\grc2639\Downloads\MScDSA\python\microblog\venv\lib\site-packages\jinja2\environment.py", line 768, in compile
    self.handle_exception(source=source_hint)
  File "C:\Users\grc2639\Downloads\MScDSA\python\microblog\venv\lib\site-packages\jinja2\environment.py", line 936, in handle_exception
    raise rewrite_traceback_stack(source=source)
  File "C:\Users\grc2639\Downloads\MScDSA\python\microblog\app\templates\404.html", line 1, in template
    {% extends 'base.html'}
jinja2.exceptions.TemplateSyntaxError: unexpected '}'
